Workbook

Sheet Dashboard
A1: Sales Performance Dashboard
A4: Total Revenue | E4: Total Profit | I4: Total Orders | M4: Profit Margin
A6: ='Pivot Table'!B6 -> 821855 | E6: ='Pivot Table'!C6 -> 245636 | I6: ='Pivot Table'!D6 -> 43 | M6: ='Pivot Table'!G6 -> 0.29887997

Sheet Pivot Table
A1: Monthly Sales Performance
A2: Order Month | B2: Revenue | C2: Profit | D2: Orders | E2: TotalCost | F2: Quantity Sold | G2: Profit Margin
A3: Jan | B3: 459990 | C3: 137220 | D3: 26 | E3: 322770 | F3: 409 | G3: =(C3/B3) -> 0.29831083
A4: Feb | B4: 337170 | C4: 101011 | D4: 15 | E4: 236159 | F4: 225 | G4: =(C4/B4) -> 0.29958478
A5: Mar | B5: 24695 | C5: 7405 | D5: 2 | E5: 17290 | F5: 26 | G5: =(C5/B5) -> 0.29985827
A6: Grand Total | B6: 821855 | C6: 245636 | D6: 43 | E6: 576219 | F6: 660 | G6: =(C6/B6) -> 0.29887997
A8: Sales Performance by City
A9: City | B9: Revenue | C9: Profit | D9: Orders | E9: Quantity | F9: Average Order Value | G9: Profit Margin
A10: Bucuresti | B10: 422205 | C10: 126294 | D10: 25 | E10: 361 | F10: =B10/D10 -> 16888.2 | G10: =C10/B10 -> 0.29912957 | I10: ='Pivot Table'!A10 -> Bucuresti | J10: Max Revenue | K10: =MAX('Pivot Table'!B10:B12) -> 422205
A11: Cluj-Napoca | B11: 268165 | C11: 80075 | D11: 13 | E11: 217 | F11: =B11/D11 -> 20628.077 | G11: =C11/B11 -> 0.29860347 | I11: ='Pivot Table'!A12 -> Iasi | J11: Min Revenue | K11: =MIN('Pivot Table'!B10:B12) -> 131485
A12: Iasi | B12: 131485 | C12: 39267 | D12: 5 | E12: 82 | F12: =B12/D12 -> 26297 | G12: =C12/B12 -> 0.29864243 | I12: ='Pivot Table'!A10 -> Bucuresti | J12: Max Profit | K12: =MAX('Pivot Table'!C10:C12) -> 126294
A13: Grand Total | B13: 821855 | C13: 245636 | D13: 43 | E13: 660 | F13: =B13/D13 -> 19112.907 | G13: =C13/B13 -> 0.29887997 | I13: ='Pivot Table'!A12 -> Iasi | J13: Min Profit | K13: =MIN('Pivot Table'!C10:C12) -> 39267
A15: Payment Method Analysis
A16: PaymentMethod_Check | B16: Orders | C16: Profit | D16: Revenue | E16: Quantity
A17: Bank Transfer | B17: 15 | C17: 62865 | D17: 211335 | E17: 199
A18: Card | B18: 11 | C18: 58370 | D18: 195080 | E18: 151
A19: Cash | B19: 6 | C19: 17526 | D19: 58525 | E19: 79
A20: Unknown | B20: 11 | C20: 106875 | D20: 356915 | E20: 231
A21: Grand Total | B21: 43 | C21: 245636 | D21: 821855 | E21: 660
A23: Salesperson Performance
A24: Salesperson | B24: Orders | C24: Revenue | D24: Profit | E24: Quantity | F24: Average Order Value
A25: Andrei | B25: 14 | C25: 183180 | D25: 54723 | E25: 220 | F25: =C25/B25 -> 13084.286
A26: George | B26: 9 | C26: 170025 | D26: 50808 | E26: 96 | F26: =C26/B26 -> 18891.667
A27: Maria | B27: 9 | C27: 172530 | D27: 51570 | E27: 136 | F27: =C27/B27 -> 19170
A28: Unknown | B28: 11 | C28: 296120 | D28: 88535 | E28: 208 | F28: =C28/B28 -> 26920
A29: Grand Total | B29: 43 | C29: 821855 | D29: 245636 | E29: 660 | F29: =C29/B29 -> 19112.907
A31: Product Performance
A32: Product | B32: Orders | C32: Orders Percentage | D32: Quantity | E32: Revenue | F32: Profit | G32: Profit Margin
A33: Office Chair | B33: 9 | C33: 0.20930233 | D33: 141 | E33: 112395 | F33: 33435 | G33: =IFERROR(F33/E33,0) -> 0.29747765
A34: Mouse Logitech | B34: 9 | C34: 0.20930233 | D34: 156 | E34: 18425 | F34: 5321 | G34: =IFERROR(F34/E34,0) -> 0.2887924
A35: Monitor Dell | B35: 16 | C35: 0.37209302 | D35: 227 | E35: 215315 | F35: 64360 | G35: =IFERROR(F35/E35,0) -> 0.2989109
A36: Laptop Lenovo | B36: 9 | C36: 0.20930233 | D36: 136 | E36: 475720 | F36: 142520 | G36: =IFERROR(F36/E36,0) -> 0.29958799
A37: Grand Total | B37: 43 | C37: 1 | D37: 660 | E37: 821855 | F37: 245636 | G37: =IFERROR(F37/E37,0) -> 0.29887997
A39: Category Performance
A40: Category | B40: Orders | C40: Quantity | D40: Profit | E40: Revenue | F40: Average Order Value
A41: Electronics | B41: 34 | C41: 519 | D41: 212201 | E41: 709460 | F41: =AVERAGE(E41/B41) -> 20866.471
A42: Furniture | B42: 9 | C42: 141 | D42: 33435 | E42: 112395 | F42: =AVERAGE(E42/B42) -> 12488.333
A43: Grand Total | B43: 43 | C43: 660 | D43: 245636 | E43: 821855 | F43: =AVERAGE(E43/B43) -> 19112.907
A45: Sales Performance by Customer
A46: CustomerName | B46: Revenue | C46: Profit | D46: Orders | E46: Quantity
...

Sheet Orders
A1: OrderID | B1: OrderID_Duplicates | C1: OrderDate | D1: OrderDate_Clean | E1: CustomerID | F1: CustomerID_Clean | G1: CustomerName | H1: CustomerName_Clean | I1: City | J1: City_Clean | K1: Product | L1: Category | M1: Category_Clean | N1: Quantity | O1: Quantity_Check | P1: UnitPrice | Q1: UnitPrice_Clean | R1: UnitPrice_Check | S1: Discount | T1: Discount_Check | U1: PaymentMethod | V1: PaymentMethod_Clean | W1: SalesPerson | X1: SaledPerson_Clean | Y1: Revenue | Z1: Transaction Status | AA1: TotalCost | AB1: CostPrice | AC1: Profit | AD1: ProfitValidSales | AE1: Profit Margin
A2: 1000 | B2: =if(countif($A$2:$A1000,A2)>1,"Duplicates","Ok") -> Ok | C2: 10/02/2025 | D2: 45698 | E2: C004 | F2: =if(E2:E1000="","Unknown",E2:E1000) -> C004 | G2: Ana Popescu | H2: {=PROPER(LOWER(TRIM(G2:G81)))} -> Ana Popescu | I2: CJ | J2: {=_xlfn.XLOOKUP(I2,Lookup!$D$2:$D$11,Lookup!$E$2:$E$11,I2)} -> Cluj-Napoca | K2: Monitor Dell | L2: Electro | M2: =VLOOKUP(L2,Lookup!G:H,2,FALSE) -> Electronics | N2: 5 | O2: =IF(N2<0,"Negative Quantity",IF(N2=0,"Zero Quantity","OK")) -> OK | P2: 950 | Q2: =ABS(P2) -> 950 | R2: =IF(P2<0,"Negative Quantity",IF(P2>=0,"OK")) -> OK | S2: 120 | T2: =if(S2:S1000="","0",S2:S1000) -> 120 | U2: Bank Transfer | V2: =IF(U2="","Unknown",IFERROR(VLOOKUP(U2,Lookup!$A$2:$B$6,2,FALSE),U2)) -> Bank Transfer | W2: Andrei | X2: =if(W2:W1000="","Unknown",W2:W1000) -> Andrei | Y2: =(N2*Q2)-T2 -> 4630 | Z2: =IF(N2<0,"Possible Return",IF(N2=0,"Invalid - Zero Quantity",IF(O2<0,"Invalid - Negative Price","Sale"))) -> Sale | AA2: =N2*AB2 -> 3325 | AB2: {=_xlfn.XLOOKUP(K2,Products!$B$2:$B$5,Products!$E$2:$E$5)} -> 665 | AC2: =Y2-AA2 -> 1305 | AD2: =IF(N2<=0,"",AC2) -> 1305 | AE2: =IF(N2<=0,"",IFERROR(AC2/Y2,0)) -> 0.28185745
A3: 1001 | B3: =if(countif($A$2:$A1001,A3)>1,"Duplicates","Ok") -> Ok | C3: 2025-01-18 | D3: 45675 | E3: C010 | F3: =if(E3:E1001="","Unknown",E3:E1001) -> C010 | G3: ELENA DUMITRU | H3: Elena Dumitru | I3: Iasi | J3: {=_xlfn.XLOOKUP(I3,Lookup!$D$2:$D$11,Lookup!$E$2:$E$11,I3)} -> Iasi | K3: Mouse Logitech | L3: electronics | M3: =VLOOKUP(L3,Lookup!G:H,2,FALSE) -> Electronics | N3: -1 | O3: =IF(N3<0,"Negative Quantity",IF(N3=0,"Zero Quantity","OK")) -> Negative Quantity | P3: 120 | Q3: =ABS(P3) -> 120 | R3: =IF(P3<0,"Negative Quantity",IF(P3>=0,"OK")) -> OK | S3: 120 | T3: =if(S3:S1001="","0",S3:S1001) -> 120 | U3: Transfer | V3: =IF(U3="","Unknown",IFERROR(VLOOKUP(U3,Lookup!$A$2:$B$6,2,FALSE),U3)) -> Bank Transfer | W3: Maria | X3: =if(W3:W1001="","Unknown",W3:W1001) -> Maria | Y3: =(N3*Q3)-T3 -> -240 | Z3: =IF(N3<0,"Possible Return",IF(N3=0,"Invalid - Zero Quantity",IF(O3<0,"Invalid - Negative Price","Sale"))) -> Possible Return | AA3: =N3*AB3 -> -84 | AB3: {=_xlfn.XLOOKUP(K3,Products!$B$2:$B$5,Products!$E$2:$E$5)} -> 84 | AC3: =Y3-AA3 -> -156 | AD3: =IF(N3<=0,"",AC3) | AE3: =IF(N3<=0,"",IFERROR(AC3/Y3,0))
A4: 1002 | B4: =if(countif($A$2:$A1002,A4)>1,"Duplicates","Ok") -> Ok | C4: 2025-01-08 | D4: 45665 | E4: C012 | F4: =if(E4:E1002="","Unknown",E4:E1002) -> C012 | G4: ELENA DUMITRU | H4: Elena Dumitru | I4: București | J4: {=_xlfn.XLOOKUP(I4,Lookup!$D$2:$D$11,Lookup!$E$2:$E$11,I4)} -> Bucuresti | K4: Mouse Logitech | L4: electronics | M4: =VLOOKUP(L4,Lookup!G:H,2,FALSE) -> Electronics | N4: 25 | O4: =IF(N4<0,"Negative Quantity",IF(N4=0,"Zero Quantity","OK")) -> OK | P4: 120 | Q4: =ABS(P4) -> 120 | R4: =IF(P4<0,"Negative Quantity",IF(P4>=0,"OK")) -> OK | S4: 120 | T4: =if(S4:S1002="","0",S4:S1002) -> 120 | U4: Bank Transfer | V4: =IF(U4="","Unknown",IFERROR(VLOOKUP(U4,Lookup!$A$2:$B$6,2,FALSE),U4)) -> Bank Transfer | X4: =if(W4:W1002="","Unknown",W4:W1002) -> Unknown | Y4: =(N4*Q4)-T4 -> 2880 | Z4: =IF(N4<0,"Possible Return",IF(N4=0,"Invalid - Zero Quantity",IF(O4<0,"Invalid - Negative Price","Sale"))) -> Sale | AA4: =N4*AB4 -> 2100 | AB4: {=_xlfn.XLOOKUP(K4,Products!$B$2:$B$5,Products!$E$2:$E$5)} -> 84 | AC4: =Y4-AA4 -> 780 | AD4: =IF(N4<=0,"",AC4) -> 780 | AE4: =IF(N4<=0,"",IFERROR(AC4/Y4,0)) -> 0.27083333
A5: 1003 | B5: =if(countif($A$2:$A1003,A5)>1,"Duplicates","Ok") -> Ok | C5: 25-Jan-25 | D5: 45682 | E5: C002 | F5: =if(E5:E1003="","Unknown",E5:E1003) -> C002 | G5: mihai ionescu | H5: Mihai Ionescu | I5: Buc. | J5: {=_xlfn.XLOOKUP(I5,Lookup!$D$2:$D$11,Lookup!$E$2:$E$11,I5)} -> Bucuresti | K5: Laptop Lenovo | L5: Electronics | M5: =VLOOKUP(L5,Lookup!G:H,2,FALSE) -> Electronics | N5: -1 | O5: =IF(N5<0,"Negative Quantity",IF(N5=0,"Zero Quantity","OK")) -> Negative Quantity | P5: 3500 | Q5: =ABS(P5) -> 3500 | R5: =IF(P5<0,"Negative Quantity",IF(P5>=0,"OK")) -> OK | S5: 5 | T5: =if(S5:S1003="","0",S5:S1003) -> 5 | U5: Cash | V5: =IF(U5="","Unknown",IFERROR(VLOOKUP(U5,Lookup!$A$2:$B$6,2,FALSE),U5)) -> Cash | W5: George | X5: =if(W5:W1003="","Unknown",W5:W1003) -> George | Y5: =(N5*Q5)-T5 -> -3505 | Z5: =IF(N5<0,"Possible Return",IF(N5=0,"Invalid - Zero Quantity",IF(O5<0,"Invalid - Negative Price","Sale"))) -> Possible Return | AA5: =N5*AB5 -> -2450 | AB5: {=_xlfn.XLOOKUP(K5,Products!$B$2:$B$5,Products!$E$2:$E$5)} -> 2450 | AC5: =Y5-AA5 -> -1055 | AD5: =IF(N5<=0,"",AC5) | AE5: =IF(N5<=0,"",IFERROR(AC5/Y5,0))
A6: 1004 | B6: =if(countif($A$2:$A1004,A6)>1,"Duplicates","Ok") -> Ok | C6: 2025-02-18 | D6: 45706 | E6: C011 | F6: =if(E6:E1004="","Unknown",E6:E1004) -> C011 | G6: MARIA ilie | H6: Maria Ilie | I6: Bucuresti | J6: {=_xlfn.XLOOKUP(I6,Lookup!$D$2:$D$11,Lookup!$E$2:$E$11,I6)} -> Bucuresti | K6: Laptop Lenovo | L6: Electronics | M6: =VLOOKUP(L6,Lookup!G:H,2,FALSE) -> Electronics | N6: 25 | O6: =IF(N6<0,"Negative Quantity",IF(N6=0,"Zero Quantity","OK")) -> OK | P6: 3500 | Q6: =ABS(P6) -> 3500 | R6: =IF(P6<0,"Negative Quantity",IF(P6>=0,"OK")) -> OK | S6: 0 | T6: =if(S6:S1004="","0",S6:S1004) -> 0 | V6: =IF(U6="","Unknown",IFERROR(VLOOKUP(U6,Lookup!$A$2:$B$6,2,FALSE),U6)) -> Unknown | W6: George | X6: =if(W6:W1004="","Unknown",W6:W1004) -> George | Y6: =(N6*Q6)-T6 -> 87500 | Z6: =IF(N6<0,"Possible Return",IF(N6=0,"Invalid - Zero Quantity",IF(O6<0,"Invalid - Negative Price","Sale"))) -> Sale | AA6: =N6*AB6 -> 61250 | AB6: {=_xlfn.XLOOKUP(K6,Products!$B$2:$B$5,Products!$E$2:$E$5)} -> 2450 | AC6: =Y6-AA6 -> 26250 | AD6: =IF(N6<=0,"",AC6) -> 26250 | AE6: =IF(N6<=0,"",IFERROR(AC6/Y6,0)) -> 0.3
A7: 1005 | B7: Needs Review | C7: 15-Jan-25 | D7: 45672 | E7: C010 | F7: =if(E7:E1005="","Unknown",E7:E1005) -> C010 | G7: MARIA ilie | H7: Maria Ilie | I7: CJ | J7: {=_xlfn.XLOOKUP(I7,Lookup!$D$2:$D$11,Lookup!$E$2:$E$11,I7)} -> Cluj-Napoca | K7: Laptop Lenovo | L7: Electronics | M7: =VLOOKUP(L7,Lookup!G:H,2,FALSE) -> Electronics | N7: 25 | O7: =IF(N7<0,"Negative Quantity",IF(N7=0,"Zero Quantity","OK")) -> OK | P7: 3500 | Q7: =ABS(P7) -> 3500 | R7: =IF(P7<0,"Negative Quantity",IF(P7>=0,"OK")) -> OK | S7: 120 | T7: =if(S7:S1005="","0",S7:S1005) -> 120 | V7: =IF(U7="","Unknown",IFERROR(VLOOKUP(U7,Lookup!$A$2:$B$6,2,FALSE),U7)) -> Unknown | W7: Maria | X7: =if(W7:W1005="","Unknown",W7:W1005) -> Maria | Y7: =(N7*Q7)-T7 -> 87380 | Z7: =IF(N7<0,"Possible Return",IF(N7=0,"Invalid - Zero Quantity",IF(O7<0,"Invalid - Negative Price","Sale"))) -> Sale | AA7: =N7*AB7 -> 61250 | AB7: {=_xlfn.XLOOKUP(K7,Products!$B$2:$B$5,Products!$E$2:$E$5)} -> 2450 | AC7: =Y7-AA7 -> 26130 | AD7: =IF(N7<=0,"",AC7) -> 26130 | AE7: =IF(N7<=0,"",IFERROR(AC7/Y7,0)) -> 0.29903868
A8: 1006 | B8: =if(countif($A$2:$A1000,A8)>1,"Duplicates","Ok") -> Ok | C8: 02-Jan-25 | D8: 45659 | E8: C025 | F8: =if(E8:E1006="","Unknown",E8:E1006) -> C025 | G8: ELENA DUMITRU | H8: Elena Dumitru | I8: București | J8: {=_xlfn.XLOOKUP(I8,Lookup!$D$2:$D$11,Lookup!$E$2:$E$11,I8)} -> Bucuresti | K8: Monitor Dell | L8: Electro | M8: =VLOOKUP(L8,Lookup!G:H,2,FALSE) -> Electronics | N8: 25 | O8: =IF(N8<0,"Negative Quantity",IF(N8=0,"Zero Quantity","OK")) -> OK | P8: 950 | Q8: =ABS(P8) -> 950 | R8: =IF(P8<0,"Negative Quantity",IF(P8>=0,"OK")) -> OK | S8: 0 | T8: =if(S8:S1006="","0",S8:S1006) -> 0 | U8: card | V8: =IF(U8="","Unknown",IFERROR(VLOOKUP(U8,Lookup!$A$2:$B$6,2,FALSE),U8)) -> Card | X8: =if(W8:W1006="","Unknown",W8:W1006) -> Unknown | Y8: =(N8*Q8)-T8 -> 23750 | Z8: =IF(N8<0,"Possible Return",IF(N8=0,"Invalid - Zero Quantity",IF(O8<0,"Invalid - Negative Price","Sale"))) -> Sale | AA8: =N8*AB8 -> 16625 | AB8: {=_xlfn.XLOOKUP(K8,Products!$B$2:$B$5,Products!$E$2:$E$5)} -> 665 | AC8: =Y8-AA8 -> 7125 | AD8: =IF(N8<=0,"",AC8) -> 7125 | AE8: =IF(N8<=0,"",IFERROR(AC8/Y8,0)) -> 0.3
A9: 1007 | B9: =if(countif($A$2:$A1001,A9)>1,"Duplicates","Ok") -> Ok | C9: 2025-02-26 | D9: 45714 | E9: C014 | F9: =if(E9:E1007="","Unknown",E9:E1007) -> C014 | G9: mihai ionescu | H9: Mihai Ionescu | I9: Buc. | J9: {=_xlfn.XLOOKUP(I9,Lookup!$D$2:$D$11,Lookup!$E$2:$E$11,I9)} -> Bucuresti | K9: Mouse Logitech | L9: electronics | M9: =VLOOKUP(L9,Lookup!G:H,2,FALSE) -> Electronics | N9: 1 | O9: =IF(N9<0,"Negative Quantity",IF(N9=0,"Zero Quantity","OK")) -> OK | P9: -120 | Q9: =ABS(P9) -> 120 | R9: =IF(P9<0,"Negative Quantity",IF(P9>=0,"OK")) -> Negative Quantity | S9: 15 | T9: =if(S9:S1007="","0",S9:S1007) -> 15 | U9: Cash | V9: =IF(U9="","Unknown",IFERROR(VLOOKUP(U9,Lookup!$A$2:$B$6,2,FALSE),U9)) -> Cash | W9: Andrei | X9: =if(W9:W1007="","Unknown",W9:W1007) -> Andrei | Y9: =(N9*Q9)-T9 -> 105 | Z9: =IF(N9<0,"Possible Return",IF(N9=0,"Invalid - Zero Quantity",IF(O9<0,"Invalid - Negative Price","Sale"))) -> Sale | AA9: =N9*AB9 -> 84 | AB9: {=_xlfn.XLOOKUP(K9,Products!$B$2:$B$5,Products!$E$2:$E$5)} -> 84 | AC9: =Y9-AA9 -> 21 | AD9: =IF(N9<=0,"",AC9) -> 21 | AE9: =IF(N9<=0,"",IFERROR(AC9/Y9,0)) -> 0.2
A10: 1008 | B10: =if(countif($A$2:$A1002,A10)>1,"Duplicates","Ok") -> Ok | C10: 15-Feb-25 | D10: 45703 | E10: C023 | F10: =if(E10:E1008="","Unknown",E10:E1008) -> C023 | G10: MARIA ilie | H10: Maria Ilie | I10: Cluj | J10: {=_xlfn.XLOOKUP(I10,Lookup!$D$2:$D$11,Lookup!$E$2:$E$11,I10)} -> Cluj-Napoca | K10: Mouse Logitech | L10: electronics | M10: =VLOOKUP(L10,Lookup!G:H,2,FALSE) -> Electronics | N10: -1 | O10: =IF(N10<0,"Negative Quantity",IF(N10=0,"Zero Quantity","OK")) -> Negative Quantity | P10: 120 | Q10: =ABS(P10) -> 120 | R10: =IF(P10<0,"Negative Quantity",IF(P10>=0,"OK")) -> OK | S10: 5 | T10: =if(S10:S1008="","0",S10:S1008) -> 5 | U10: Transfer | V10: =IF(U10="","Unknown",IFERROR(VLOOKUP(U10,Lookup!$A$2:$B$6,2,FALSE),U10)) -> Bank Transfer | W10: Andrei | X10: =if(W10:W1008="","Unknown",W10:W1008) -> Andrei | Y10: =(N10*Q10)-T10 -> -125 | Z10: =IF(N10<0,"Possible Return",IF(N10=0,"Invalid - Zero Quantity",IF(O10<0,"Invalid - Negative Price","Sale"))) -> Possible Return | AA10: =N10*AB10 -> -84 | AB10: {=_xlfn.XLOOKUP(K10,Products!$B$2:$B$5,Products!$E$2:$E$5)} -> 84 | AC10: =Y10-AA10 -> -41 | AD10: =IF(N10<=0,"",AC10) | AE10: =IF(N10<=0,"",IFERROR(AC10/Y10,0))
A11: 1009 | B11: =if(countif($A$2:$A1003,A11)>1,"Duplicates","Ok") -> Ok | C11: 18-Feb-25 | D11: 45706 | E11: C005 | F11: =if(E11:E1009="","Unknown",E11:E1009) -> C005 | G11: mihai ionescu | H11: Mihai Ionescu | I11: CJ | J11: {=_xlfn.XLOOKUP(I11,Lookup!$D$2:$D$11,Lookup!$E$2:$E$11,I11)} -> Cluj-Napoca | K11: Office Chair | L11: Furniture | M11: =VLOOKUP(L11,Lookup!G:H,2,FALSE) -> Furniture | N11: 25 | O11: =IF(N11<0,"Negative Quantity",IF(N11=0,"Zero Quantity","OK")) -> OK | P11: 800 | Q11: =ABS(P11) -> 800 | R11: =IF(P11<0,"Negative Quantity",IF(P11>=0,"OK")) -> OK | S11: 10 | T11: =if(S11:S1009="","0",S11:S1009) -> 10 | V11: =IF(U11="","Unknown",IFERROR(VLOOKUP(U11,Lookup!$A$2:$B$6,2,FALSE),U11)) -> Unknown | W11: Maria | X11: =if(W11:W1009="","Unknown",W11:W1009) -> Maria | Y11: =(N11*Q11)-T11 -> 19990 | Z11: =IF(N11<0,"Possible Return",IF(N11=0,"Invalid - Zero Quantity",IF(O11<0,"Invalid - Negative Price","Sale"))) -> Sale | AA11: =N11*AB11 -> 14000 | AB11: {=_xlfn.XLOOKUP(K11,Products!$B$2:$B$5,Products!$E$2:$E$5)} -> 560 | AC11: =Y11-AA11 -> 5990 | AD11: =IF(N11<=0,"",AC11) -> 5990 | AE11: =IF(N11<=0,"",IFERROR(AC11/Y11,0)) -> 0.29964982
A12: 1010 | B12: =if(countif($A$2:$A1004,A12)>1,"Duplicates","Ok") -> Ok | C12: 16-Feb-25 | D12: 45704 | E12: C009 | F12: =if(E12:E1010="","Unknown",E12:E1010) -> C009 | G12: mihai ionescu | H12: Mihai Ionescu | I12: CJ | J12: {=_xlfn.XLOOKUP(I12,Lookup!$D$2:$D$11,Lookup!$E$2:$E$11,I12)} -> Cluj-Napoca | K12: Laptop Lenovo | L12: Electronics | M12: =VLOOKUP(L12,Lookup!G:H,2,FALSE) -> Electronics | N12: 2 | O12: =IF(N12<0,"Negative Quantity",IF(N12=0,"Zero Quantity","OK")) -> OK | P12: 3500 | Q12: =ABS(P12) -> 3500 | R12: =IF(P12<0,"Negative Quantity",IF(P12>=0,"OK")) -> OK | T12: =if(S12:S1010="","0",S12:S1010) -> 0 | U12: Cash | V12: =IF(U12="","Unknown",IFERROR(VLOOKUP(U12,Lookup!$A$2:$B$6,2,FALSE),U12)) -> Cash | W12: George | X12: =if(W12:W1010="","Unknown",W12:W1010) -> George | Y12: =(N12*Q12)-T12 -> 7000 | Z12: =IF(N12<0,"Possible Return",IF(N12=0,"Invalid - Zero Quantity",IF(O12<0,"Invalid - Negative Price","Sale"))) -> Sale | AA12: =N12*AB12 -> 4900 | AB12: {=_xlfn.XLOOKUP(K12,Products!$B$2:$B$5,Products!$E$2:$E$5)} -> 2450 | AC12: =Y12-AA12 -> 2100 | AD12: =IF(N12<=0,"",AC12) -> 2100 | AE12: =IF(N12<=0,"",IFERROR(AC12/Y12,0)) -> 0.3
A13: 1011 | B13: =if(countif($A$2:$A1005,A13)>1,"Duplicates","Ok") -> Ok | C13: 13-Jan-25 | D13: 45670 | E13: C022 | F13: =if(E13:E1011="","Unknown",E13:E1011) -> C022 | G13: mihai ionescu | H13: Mihai Ionescu | I13: BUCURESTI | J13: {=_xlfn.XLOOKUP(I13,Lookup!$D$2:$D$11,Lookup!$E$2:$E$11,I13)} -> Bucuresti | K13: Mouse Logitech | L13: electronics | M13: =VLOOKUP(L13,Lookup!G:H,2,FALSE) -> Electronics | N13: 25 | O13: =IF(N13<0,"Negative Quantity",IF(N13=0,"Zero Quantity","OK")) -> OK | P13: 120 | Q13: =ABS(P13) -> 120 | R13: =IF(P13<0,"Negative Quantity",IF(P13>=0,"OK")) -> OK | S13: 15 | T13: =if(S13:S1011="","0",S13:S1011) -> 15 | U13: Card | V13: =IF(U13="","Unknown",IFERROR(VLOOKUP(U13,Lookup!$A$2:$B$6,2,FALSE),U13)) -> Card | W13: Andrei | X13: =if(W13:W1011="","Unknown",W13:W1011) -> Andrei | Y13: =(N13*Q13)-T13 -> 2985 | Z13: =IF(N13<0,"Possible Return",IF(N13=0,"Invalid - Zero Quantity",IF(O13<0,"Invalid - Negative Price","Sale"))) -> Sale | AA13: =N13*AB13 -> 2100 | AB13: {=_xlfn.XLOOKUP(K13,Products!$B$2:$B$5,Products!$E$2:$E$5)} -> 84 | AC13: =Y13-AA13 -> 885 | AD13: =IF(N13<=0,"",AC13) -> 885 | AE13: =IF(N13<=0,"",IFERROR(AC13/Y13,0)) -> 0.29648241
A14: 1012 | B14: =if(countif($A$2:$A1006,A14)>1,"Duplicates","Ok") -> Ok | C14: 2025-01-08 | D14: 45665 | E14: C021 | F14: =if(E14:E1012="","Unknown",E14:E1012) -> C021 | G14: ELENA DUMITRU | H14: Elena Dumitru | I14: Bucuresti | J14: {=_xlfn.XLOOKUP(I14,Lookup!$D$2:$D$11,Lookup!$E$2:$E$11,I14)} -> Bucuresti | K14: Laptop Lenovo | L14: Electronics | M14: =VLOOKUP(L14,Lookup!G:H,2,FALSE) -> Electronics | N14: 25 | O14: =IF(N14<0,"Negative Quantity",IF(N14=0,"Zero Quantity","OK")) -> OK | P14: 3500 | Q14: =ABS(P14) -> 3500 | R14: =IF(P14<0,"Negative Quantity",IF(P14>=0,"OK")) -> OK | S14: 10 | T14: =if(S14:S1012="","0",S14:S1012) -> 10 | V14: =IF(U14="","Unknown",IFERROR(VLOOKUP(U14,Lookup!$A$2:$B$6,2,FALSE),U14)) -> Unknown | X14: =if(W14:W1012="","Unknown",W14:W1012) -> Unknown | Y14: =(N14*Q14)-T14 -> 87490 | Z14: =IF(N14<0,"Possible Return",IF(N14=0,"Invalid - Zero Quantity",IF(O14<0,"Invalid - Negative Price","Sale"))) -> Sale | AA14: =N14*AB14 -> 61250 | AB14: {=_xlfn.XLOOKUP(K14,Products!$B$2:$B$5,Products!$E$2:$E$5)} -> 2450 | AC14: =Y14-AA14 -> 26240 | AD14: =IF(N14<=0,"",AC14) -> 26240 | AE14: =IF(N14<=0,"",IFERROR(AC14/Y14,0)) -> 0.29991999
A15: 1013 | B15: =if(countif($A$2:$A1007,A15)>1,"Duplicates","Ok") -> Ok | C15: 15/01/2025 | D15: 45672 | E15: C016 | F15: =if(E15:E1013="","Unknown",E15:E1013) -> C016 | G15: Ioana Stan | H15: Ioana Stan | I15: CJ | J15: {=_xlfn.XLOOKUP(I15,Lookup!$D$2:$D$11,Lookup!$E$2:$E$11,I15)} -> Cluj-Napoca | K15: Mouse Logitech | L15: electronics | M15: =VLOOKUP(L15,Lookup!G:H,2,FALSE) -> Electronics | N15: -1 | O15: =IF(N15<0,"Negative Quantity",IF(N15=0,"Zero Quantity","OK")) -> Negative Quantity | P15: 120 | Q15: =ABS(P15) -> 120 | R15: =IF(P15<0,"Negative Quantity",IF(P15>=0,"OK")) -> OK | S15: 10 | T15: =if(S15:S1013="","0",S15:S1013) -> 10 | U15: Cash | V15: =IF(U15="","Unknown",IFERROR(VLOOKUP(U15,Lookup!$A$2:$B$6,2,FALSE),U15)) -> Cash | X15: =if(W15:W1013="","Unknown",W15:W1013) -> Unknown | Y15: =(N15*Q15)-T15 -> -130 | Z15: =IF(N15<0,"Possible Return",IF(N15=0,"Invalid - Zero Quantity",IF(O15<0,"Invalid - Negative Price","Sale"))) -> Possible Return | AA15: =N15*AB15 -> -84 | AB15: {=_xlfn.XLOOKUP(K15,Products!$B$2:$B$5,Products!$E$2:$E$5)} -> 84 | AC15: =Y15-AA15 -> -46 | AD15: =IF(N15<=0,"",AC15) | AE15: =IF(N15<=0,"",IFERROR(AC15/Y15,0))
A16: 1014 | B16: =if(countif($A$2:$A1008,A16)>1,"Duplicates","Ok") -> Ok | C16: 13/01/2025 | D16: 45670 | E16: C024 | F16: =if(E16:E1014="","Unknown",E16:E1014) -> C024 | G16: MARIA ilie | H16: Maria Ilie | I16: Cluj-Napoca | J16: {=_xlfn.XLOOKUP(I16,Lookup!$D$2:$D$11,Lookup!$E$2:$E$11,I16)} -> Cluj-Napoca | K16: Monitor Dell | L16: Electro | M16: =VLOOKUP(L16,Lookup!G:H,2,FALSE) -> Electronics | N16: 3 | O16: =IF(N16<0,"Negative Quantity",IF(N16=0,"Zero Quantity","OK")) -> OK | P16: 950 | Q16: =ABS(P16) -> 950 | R16: =IF(P16<0,"Negative Quantity",IF(P16>=0,"OK")) -> OK | S16: 10 | T16: =if(S16:S1014="","0",S16:S1014) -> 10 | U16: card | V16: =IF(U16="","Unknown",IFERROR(VLOOKUP(U16,Lookup!$A$2:$B$6,2,FALSE),U16)) -> Card | W16: Maria | X16: =if(W16:W1014="","Unknown",W16:W1014) -> Maria | Y16: =(N16*Q16)-T16 -> 2840 | Z16: =IF(N16<0,"Possible Return",IF(N16=0,"Invalid - Zero Quantity",IF(O16<0,"Invalid - Negative Price","Sale"))) -> Sale | AA16: =N16*AB16 -> 1995 | AB16: {=_xlfn.XLOOKUP(K16,Products!$B$2:$B$5,Products!$E$2:$E$5)} -> 665 | AC16: =Y16-AA16 -> 845 | AD16: =IF(N16<=0,"",AC16) -> 845 | AE16: =IF(N16<=0,"",IFERROR(AC16/Y16,0)) -> 0.29753521
A17: 1015 | B17: =if(countif($A$2:$A1009,A17)>1,"Duplicates","Ok") -> Ok | C17: 01-Mar-25 | D17: 45717 | F17: =if(E17:E1015="","Unknown",E17:E1015) -> Unknown | G17: Ana Popescu | H17: Ana Popescu | I17: București | J17: {=_xlfn.XLOOKUP(I17,Lookup!$D$2:$D$11,Lookup!$E$2:$E$11,I17)} -> Bucuresti | K17: Monitor Dell | L17: Electro | M17: =VLOOKUP(L17,Lookup!G:H,2,FALSE) -> Electronics | N17: 0 | O17: =IF(N17<0,"Negative Quantity",IF(N17=0,"Zero Quantity","OK")) -> Zero Quantity | P17: 950 | Q17: =ABS(P17) -> 950 | R17: =IF(P17<0,"Negative Quantity",IF(P17>=0,"OK")) -> OK | T17: =if(S17:S1015="","0",S17:S1015) -> 0 | V17: =IF(U17="","Unknown",IFERROR(VLOOKUP(U17,Lookup!$A$2:$B$6,2,FALSE),U17)) -> Unknown | W17: Maria | X17: =if(W17:W1015="","Unknown",W17:W1015) -> Maria | Y17: =(N17*Q17)-T17 -> 0 | Z17: =IF(N17<0,"Possible Return",IF(N17=0,"Invalid - Zero Quantity",IF(O17<0,"Invalid - Negative Price","Sale"))) -> Invalid - Zero Quantity | AA17: =N17*AB17 -> 0 | AB17: {=_xlfn.XLOOKUP(K17,Products!$B$2:$B$5,Products!$E$2:$E$5)} -> 665 | AC17: =Y17-AA17 -> 0 | AD17: =IF(N17<=0,"",AC17) | AE17: =IF(N17<=0,"",IFERROR(AC17/Y17,0))
A18: 1016 | B18: =if(countif($A$2:$A1010,A18)>1,"Duplicates","Ok") -> Ok | C18: 07-Jan-25 | D18: 45664 | E18: C011 | F18: =if(E18:E1016="","Unknown",E18:E1016) -> C011 | G18: Ioana Stan | H18: Ioana Stan | I18: CJ | J18: {=_xlfn.XLOOKUP(I18,Lookup!$D$2:$D$11,Lookup!$E$2:$E$11,I18)} -> Cluj-Napoca | K18: Monitor Dell | L18: Electro | M18: =VLOOKUP(L18,Lookup!G:H,2,FALSE) -> Electronics | N18: 25 | O18: =IF(N18<0,"Negative Quantity",IF(N18=0,"Zero Quantity","OK")) -> OK | P18: 950 | Q18: =ABS(P18) -> 950 | R18: =IF(P18<0,"Negative Quantity",IF(P18>=0,"OK")) -> OK | S18: 120 | T18: =if(S18:S1016="","0",S18:S1016) -> 120 | U18: card | V18: =IF(U18="","Unknown",IFERROR(VLOOKUP(U18,Lookup!$A$2:$B$6,2,FALSE),U18)) -> Card | W18: George | X18: =if(W18:W1016="","Unknown",W18:W1016) -> George | Y18: =(N18*Q18)-T18 -> 23630 | Z18: =IF(N18<0,"Possible Return",IF(N18=0,"Invalid - Zero Quantity",IF(O18<0,"Invalid - Negative Price","Sale"))) -> Sale | AA18: =N18*AB18 -> 16625 | AB18: {=_xlfn.XLOOKUP(K18,Products!$B$2:$B$5,Products!$E$2:$E$5)} -> 665 | AC18: =Y18-AA18 -> 7005 | AD18: =IF(N18<=0,"",AC18) -> 7005 | AE18: =IF(N18<=0,"",IFERROR(AC18/Y18,0)) -> 0.2964452
A19: 1017 | B19: =if(countif($A$2:$A1011,A19)>1,"Duplicates","Ok") -> Ok | C19: 2025-01-13 | D19: 45670 | E19: C015 | F19: =if(E19:E1017="","Unknown",E19:E1017) -> C015 | G19: mihai ionescu | H19: Mihai Ionescu | I19: Cluj-Napoca | J19: {=_xlfn.XLOOKUP(I19,Lookup!$D$2:$D$11,Lookup!$E$2:$E$11,I19)} -> Cluj-Napoca | K19: Office Chair | L19: Furniture | M19: =VLOOKUP(L19,Lookup!G:H,2,FALSE) -> Furniture | N19: 25 | O19: =IF(N19<0,"Negative Quantity",IF(N19=0,"Zero Quantity","OK")) -> OK | P19: 800 | Q19: =ABS(P19) -> 800 | R19: =IF(P19<0,"Negative Quantity",IF(P19>=0,"OK")) -> OK | S19: 15 | T19: =if(S19:S1017="","0",S19:S1017) -> 15 | V19: =IF(U19="","Unknown",IFERROR(VLOOKUP(U19,Lookup!$A$2:$B$6,2,FALSE),U19)) -> Unknown | X19: =if(W19:W1017="","Unknown",W19:W1017) -> Unknown | Y19: =(N19*Q19)-T19 -> 19985 | Z19: =IF(N19<0,"Possible Return",IF(N19=0,"Invalid - Zero Quantity",IF(O19<0,"Invalid - Negative Price","Sale"))) -> Sale | AA19: =N19*AB19 -> 14000 | AB19: {=_xlfn.XLOOKUP(K19,Products!$B$2:$B$5,Products!$E$2:$E$5)} -> 560 | AC19: =Y19-AA19 -> 5985 | AD19: =IF(N19<=0,"",AC19) -> 5985 | AE19: =IF(N19<=0,"",IFERROR(AC19/Y19,0)) -> 0.29947461
A20: 1018 | B20: =if(countif($A$2:$A1012,A20)>1,"Duplicates","Ok") -> Ok | C20: 11-Jan-25 | D20: 45668 | E20: C013 | F20: =if(E20:E1018="","Unknown",E20:E1018) -> C013 | G20: mihai ionescu | H20: Mihai Ionescu | I20: Cluj | J20: {=_xlfn.XLOOKUP(I20,Lookup!$D$2:$D$11,Lookup!$E$2:$E$11,I20)} -> Cluj-Napoca | K20: Mouse Logitech | L20: electronics | M20: =VLOOKUP(L20,Lookup!G:H,2,FALSE) -> Electronics | N20: 25 | O20: =IF(N20<0,"Negative Quantity",IF(N20=0,"Zero Quantity","OK")) -> OK | P20: 120 | Q20: =ABS(P20) -> 120 | R20: =IF(P20<0,"Negative Quantity",IF(P20>=0,"OK")) -> OK | T20: =if(S20:S1018="","0",S20:S1018) -> 0 | U20: Bank Transfer | V20: =IF(U20="","Unknown",IFERROR(VLOOKUP(U20,Lookup!$A$2:$B$6,2,FALSE),U20)) -> Bank Transfer | W20: Andrei | X20: =if(W20:W1018="","Unknown",W20:W1018) -> Andrei | Y20: =(N20*Q20)-T20 -> 3000 | Z20: =IF(N20<0,"Possible Return",IF(N20=0,"Invalid - Zero Quantity",IF(O20<0,"Invalid - Negative Price","Sale"))) -> Sale | AA20: =N20*AB20 -> 2100 | AB20: {=_xlfn.XLOOKUP(K20,Products!$B$2:$B$5,Products!$E$2:$E$5)} -> 84 | AC20: =Y20-AA20 -> 900 | AD20: =IF(N20<=0,"",AC20) -> 900 | AE20: =IF(N20<=0,"",IFERROR(AC20/Y20,0)) -> 0.3
A21: 1019 | B21: =if(countif($A$2:$A1013,A21)>1,"Duplicates","Ok") -> Ok | C21: 14/01/2025 | D21: 45671 | E21: C008 | F21: =if(E21:E1019="","Unknown",E21:E1019) -> C008 | G21: MARIA ilie | H21: Maria Ilie | I21: Iași | J21: {=_xlfn.XLOOKUP(I21,Lookup!$D$2:$D$11,Lookup!$E$2:$E$11,I21)} -> Iasi | K21: Mouse Logitech | L21: electronics | M21: =VLOOKUP(L21,Lookup!G:H,2,FALSE) -> Electronics | N21: 2 | O21: =IF(N21<0,"Negative Quantity",IF(N21=0,"Zero Quantity","OK")) -> OK | P21: 120 | Q21: =ABS(P21) -> 120 | R21: =IF(P21<0,"Negative Quantity",IF(P21>=0,"OK")) -> OK | S21: 120 | T21: =if(S21:S1019="","0",S21:S1019) -> 120 | U21: Transfer | V21: =IF(U21="","Unknown",IFERROR(VLOOKUP(U21,Lookup!$A$2:$B$6,2,FALSE),U21)) -> Bank Transfer | W21: Andrei | X21: =if(W21:W1019="","Unknown",W21:W1019) -> Andrei | Y21: =(N21*Q21)-T21 -> 120 | Z21: =IF(N21<0,"Possible Return",IF(N21=0,"Invalid - Zero Quantity",IF(O21<0,"Invalid - Negative Price","Sale"))) -> Sale | AA21: =N21*AB21 -> 168 | AB21: {=_xlfn.XLOOKUP(K21,Products!$B$2:$B$5,Products!$E$2:$E$5)} -> 84 | AC21: =Y21-AA21 -> -48 | AD21: =IF(N21<=0,"",AC21) -> -48 | AE21: =IF(N21<=0,"",IFERROR(AC21/Y21,0)) -> -0.4
A22: 1005 | B22: Possible Return | C22: 2025-01-26 | D22: 45683 | F22: =if(E22:E1020="","Unknown",E22:E1020) -> Unknown | G22: Ioana Stan | H22: Ioana Stan | I22: CJ | J22: {=_xlfn.XLOOKUP(I22,Lookup!$D$2:$D$11,Lookup!$E$2:$E$11,I22)} -> Cluj-Napoca | K22: Office Chair | L22: Furniture | M22: =VLOOKUP(L22,Lookup!G:H,2,FALSE) -> Furniture | N22: -1 | O22: =IF(N22<0,"Negative Quantity",IF(N22=0,"Zero Quantity","OK")) -> Negative Quantity | P22: 800 | Q22: =ABS(P22) -> 800 | R22: =IF(P22<0,"Negative Quantity",IF(P22>=0,"OK")) -> OK | T22: =if(S22:S1020="","0",S22:S1020) -> 0 | U22: card | V22: =IF(U22="","Unknown",IFERROR(VLOOKUP(U22,Lookup!$A$2:$B$6,2,FALSE),U22)) -> Card | W22: Maria | X22: =if(W22:W1020="","Unknown",W22:W1020) -> Maria | Y22: =(N22*Q22)-T22 -> -800 | Z22: =IF(N22<0,"Possible Return",IF(N22=0,"Invalid - Zero Quantity",IF(O22<0,"Invalid - Negative Price","Sale"))) -> Possible Return | AA22: =N22*AB22 -> -560 | AB22: {=_xlfn.XLOOKUP(K22,Products!$B$2:$B$5,Products!$E$2:$E$5)} -> 560 | AC22: =Y22-AA22 -> -240 | AD22: =IF(N22<=0,"",AC22) | AE22: =IF(N22<=0,"",IFERROR(AC22/Y22,0))
A23: 1021 | B23: =if(countif($A$2:$A1000,A23)>1,"Duplicates","Ok") -> Ok | C23: 12-Jan-25 | D23: 45669 | E23: C008 | F23: =if(E23:E1021="","Unknown",E23:E1021) -> C008 | G23: Ioana Stan | H23: Ioana Stan | I23: Buc. | J23: {=_xlfn.XLOOKUP(I23,Lookup!$D$2:$D$11,Lookup!$E$2:$E$11,I23)} -> Bucuresti | K23: Monitor Dell | L23: Electro | M23: =VLOOKUP(L23,Lookup!G:H,2,FALSE) -> Electronics | N23: 0 | O23: =IF(N23<0,"Negative Quantity",IF(N23=0,"Zero Quantity","OK")) -> Zero Quantity | P23: 950 | Q23: =ABS(P23) -> 950 | R23: =IF(P23<0,"Negative Quantity",IF(P23>=0,"OK")) -> OK | S23: 5 | T23: =if(S23:S1021="","0",S23:S1021) -> 5 | U23: Bank Transfer | V23: =IF(U23="","Unknown",IFERROR(VLOOKUP(U23,Lookup!$A$2:$B$6,2,FALSE),U23)) -> Bank Transfer | W23: George | X23: =if(W23:W1021="","Unknown",W23:W1021) -> George | Y23: =(N23*Q23)-T23 -> -5 | Z23: =IF(N23<0,"Possible Return",IF(N23=0,"Invalid - Zero Quantity",IF(O23<0,"Invalid - Negative Price","Sale"))) -> Invalid - Zero Quantity | AA23: =N23*AB23 -> 0 | AB23: {=_xlfn.XLOOKUP(K23,Products!$B$2:$B$5,Products!$E$2:$E$5)} -> 665 | AC23: =Y23-AA23 -> -5 | AD23: =IF(N23<=0,"",AC23) | AE23: =IF(N23<=0,"",IFERROR(AC23/Y23,0))
A24: 1022 | B24: =if(countif($A$2:$A1001,A24)>1,"Duplicates","Ok") -> Ok | C24: 09/01/2025 | D24: 45666 | E24: C003 | F24: =if(E24:E1022="","Unknown",E24:E1022) -> C003 | G24: mihai ionescu | H24: Mihai Ionescu | I24: Cluj | J24: {=_xlfn.XLOOKUP(I24,Lookup!$D$2:$D$11,Lookup!$E$2:$E$11,I24)} -> Cluj-Napoca | K24: Mouse Logitech | L24: electronics | M24: =VLOOKUP(L24,Lookup!G:H,2,FALSE) -> Electronics | N24: 25 | O24: =IF(N24<0,"Negative Quantity",IF(N24=0,"Zero Quantity","OK")) -> OK | P24: 120 | Q24: =ABS(P24) -> 120 | R24: =IF(P24<0,"Negative Quantity",IF(P24>=0,"OK")) -> OK | S24: 10 | T24: =if(S24:S1022="","0",S24:S1022) -> 10 | V24: =IF(U24="","Unknown",IFERROR(VLOOKUP(U24,Lookup!$A$2:$B$6,2,FALSE),U24)) -> Unknown | W24: Andrei | X24: =if(W24:W1022="","Unknown",W24:W1022) -> Andrei | Y24: =(N24*Q24)-T24 -> 2990 | Z24: =IF(N24<0,"Possible Return",IF(N24=0,"Invalid - Zero Quantity",IF(O24<0,"Invalid - Negative Price","Sale"))) -> Sale | AA24: =N24*AB24 -> 2100 | AB24: {=_xlfn.XLOOKUP(K24,Products!$B$2:$B$5,Products!$E$2:$E$5)} -> 84 | AC24: =Y24-AA24 -> 890 | AD24: =IF(N24<=0,"",AC24) -> 890 | AE24: =IF(N24<=0,"",IFERROR(AC24/Y24,0)) -> 0.29765886
A25: 1023 | B25: =if(countif($A$2:$A1002,A25)>1,"Duplicates","Ok") -> Ok | C25: 21/02/2025 | D25: 45709 | E25: C013 | F25: =if(E25:E1023="","Unknown",E25:E1023) -> C013 | G25: MARIA ilie | H25: Maria Ilie | I25: Bucuresti | J25: {=_xlfn.XLOOKUP(I25,Lookup!$D$2:$D$11,Lookup!$E$2:$E$11,I25)} -> Bucuresti | K25: Mouse Logitech | L25: electronics | M25: =VLOOKUP(L25,Lookup!G:H,2,FALSE) -> Electronics | N25: 0 | O25: =IF(N25<0,"Negative Quantity",IF(N25=0,"Zero Quantity","OK")) -> Zero Quantity | P25: 120 | Q25: =ABS(P25) -> 120 | R25: =IF(P25<0,"Negative Quantity",IF(P25>=0,"OK")) -> OK | S25: 15 | T25: =if(S25:S1023="","0",S25:S1023) -> 15 | U25: Bank Transfer | V25: =IF(U25="","Unknown",IFERROR(VLOOKUP(U25,Lookup!$A$2:$B$6,2,FALSE),U25)) -> Bank Transfer | W25: Maria | X25: =if(W25:W1023="","Unknown",W25:W1023) -> Maria | Y25: =(N25*Q25)-T25 -> -15 | Z25: =IF(N25<0,"Possible Return",IF(N25=0,"Invalid - Zero Quantity",IF(O25<0,"Invalid - Negative Price","Sale"))) -> Invalid - Zero Quantity | AA25: =N25*AB25 -> 0 | AB25: {=_xlfn.XLOOKUP(K25,Products!$B$2:$B$5,Products!$E$2:$E$5)} -> 84 | AC25: =Y25-AA25 -> -15 | AD25: =IF(N25<=0,"",AC25) | AE25: =IF(N25<=0,"",IFERROR(AC25/Y25,0))
A26: 1024 | B26: =if(countif($A$2:$A1003,A26)>1,"Duplicates","Ok") -> Ok | C26: 02-Mar-25 | D26: 45718 | E26: C007 | F26: =if(E26:E1024="","Unknown",E26:E1024) -> C007 | G26: Ana Popescu | H26: Ana Popescu | I26: Iasi | J26: {=_xlfn.XLOOKUP(I26,Lookup!$D$2:$D$11,Lookup!$E$2:$E$11,I26)} -> Iasi | K26: Mouse Logitech | L26: electronics | M26: =VLOOKUP(L26,Lookup!G:H,2,FALSE) -> Electronics | N26: 0 | O26: =IF(N26<0,"Negative Quantity",IF(N26=0,"Zero Quantity","OK")) -> Zero Quantity | P26: -120 | Q26: =ABS(P26) -> 120 | R26: =IF(P26<0,"Negative Quantity",IF(P26>=0,"OK")) -> Negative Quantity | S26: 15 | T26: =if(S26:S1024="","0",S26:S1024) -> 15 | U26: Cash | V26: =IF(U26="","Unknown",IFERROR(VLOOKUP(U26,Lookup!$A$2:$B$6,2,FALSE),U26)) -> Cash | W26: George | X26: =if(W26:W1024="","Unknown",W26:W1024) -> George | Y26: =(N26*Q26)-T26 -> -15 | Z26: =IF(N26<0,"Possible Return",IF(N26=0,"Invalid - Zero Quantity",IF(O26<0,"Invalid - Negative Price","Sale"))) -> Invalid - Zero Quantity | AA26: =N26*AB26 -> 0 | AB26: {=_xlfn.XLOOKUP(K26,Products!$B$2:$B$5,Products!$E$2:$E$5)} -> 84 | AC26: =Y26-AA26 -> -15 | AD26: =IF(N26<=0,"",AC26) | AE26: =IF(N26<=0,"",IFERROR(AC26/Y26,0))
A27: 1025 | B27: =if(countif($A$2:$A1004,A27)>1,"Duplicates","Ok") -> Ok | C27: 2025-01-14 | D27: 45671 | E27: C016 | F27: =if(E27:E1025="","Unknown",E27:E1025) -> C016 | G27: ELENA DUMITRU | H27: Elena Dumitru | I27: BUCURESTI | J27: {=_xlfn.XLOOKUP(I27,Lookup!$D$2:$D$11,Lookup!$E$2:$E$11,I27)} -> Bucuresti | K27: Laptop Lenovo | L27: Electronics | M27: =VLOOKUP(L27,Lookup!G:H,2,FALSE) -> Electronics | N27: 2 | O27: =IF(N27<0,"Negative Quantity",IF(N27=0,"Zero Quantity","OK")) -> OK | P27: 3500 | Q27: =ABS(P27) -> 3500 | R27: =IF(P27<0,"Negative Quantity",IF(P27>=0,"OK")) -> OK | S27: 120 | T27: =if(S27:S1025="","0",S27:S1025) -> 120 | U27: Transfer | V27: =IF(U27="","Unknown",IFERROR(VLOOKUP(U27,Lookup!$A$2:$B$6,2,FALSE),U27)) -> Bank Transfer | W27: Maria | X27: =if(W27:W1025="","Unknown",W27:W1025) -> Maria | Y27: =(N27*Q27)-T27 -> 6880 | Z27: =IF(N27<0,"Possible Return",IF(N27=0,"Invalid - Zero Quantity",IF(O27<0,"Invalid - Negative Price","Sale"))) -> Sale | AA27: =N27*AB27 -> 4900 | AB27: {=_xlfn.XLOOKUP(K27,Products!$B$2:$B$5,Products!$E$2:$E$5)} -> 2450 | AC27: =Y27-AA27 -> 1980 | AD27: =IF(N27<=0,"",AC27) -> 1980 | AE27: =IF(N27<=0,"",IFERROR(AC27/Y27,0)) -> 0.2877907
A28: 1026 | B28: =if(countif($A$2:$A1005,A28)>1,"Duplicates","Ok") -> Ok | C28: 01/02/2025 | D28: 45689 | E28: C020 | F28: =if(E28:E1026="","Unknown",E28:E1026) -> C020 | G28: alex marin | H28: Alex Marin | I28: Bucuresti | J28: {=_xlfn.XLOOKUP(I28,Lookup!$D$2:$D$11,Lookup!$E$2:$E$11,I28)} -> Bucuresti | K28: Laptop Lenovo | L28: Electronics | M28: =VLOOKUP(L28,Lookup!G:H,2,FALSE) -> Electronics | N28: -1 | O28: =IF(N28<0,"Negative Quantity",IF(N28=0,"Zero Quantity","OK")) -> Negative Quantity | P28: 3500 | Q28: =ABS(P28) -> 3500 | R28: =IF(P28<0,"Negative Quantity",IF(P28>=0,"OK")) -> OK | S28: 120 | T28: =if(S28:S1026="","0",S28:S1026) -> 120 | U28: Transfer | V28: =IF(U28="","Unknown",IFERROR(VLOOKUP(U28,Lookup!$A$2:$B$6,2,FALSE),U28)) -> Bank Transfer | W28: Maria | X28: =if(W28:W1026="","Unknown",W28:W1026) -> Maria | Y28: =(N28*Q28)-T28 -> -3620 | Z28: =IF(N28<0,"Possible Return",IF(N28=0,"Invalid - Zero Quantity",IF(O28<0,"Invalid - Negative Price","Sale"))) -> Possible Return | AA28: =N28*AB28 -> -2450 | AB28: {=_xlfn.XLOOKUP(K28,Products!$B$2:$B$5,Products!$E$2:$E$5)} -> 2450 | AC28: =Y28-AA28 -> -1170 | AD28: =IF(N28<=0,"",AC28) | AE28: =IF(N28<=0,"",IFERROR(AC28/Y28,0))
A29: 1027 | B29: =if(countif($A$2:$A1006,A29)>1,"Duplicates","Ok") -> Ok | C29: 2025-02-12 | D29: 45700 | E29: C024 | F29: =if(E29:E1027="","Unknown",E29:E1027) -> C024 | G29: mihai ionescu | H29: Mihai Ionescu | I29: Cluj-Napoca | J29: {=_xlfn.XLOOKUP(I29,Lookup!$D$2:$D$11,Lookup!$E$2:$E$11,I29)} -> Cluj-Napoca | K29: Laptop Lenovo | L29: Electronics | M29: =VLOOKUP(L29,Lookup!G:H,2,FALSE) -> Electronics | N29: 0 | O29: =IF(N29<0,"Negative Quantity",IF(N29=0,"Zero Quantity","OK")) -> Zero Quantity | P29: 3500 | Q29: =ABS(P29) -> 3500 | R29: =IF(P29<0,"Negative Quantity",IF(P29>=0,"OK")) -> OK | S29: 15 | T29: =if(S29:S1027="","0",S29:S1027) -> 15 | U29: Transfer | V29: =IF(U29="","Unknown",IFERROR(VLOOKUP(U29,Lookup!$A$2:$B$6,2,FALSE),U29)) -> Bank Transfer | X29: =if(W29:W1027="","Unknown",W29:W1027) -> Unknown | Y29: =(N29*Q29)-T29 -> -15 | Z29: =IF(N29<0,"Possible Return",IF(N29=0,"Invalid - Zero Quantity",IF(O29<0,"Invalid - Negative Price","Sale"))) -> Invalid - Zero Quantity | AA29: =N29*AB29 -> 0 | AB29: {=_xlfn.XLOOKUP(K29,Products!$B$2:$B$5,Products!$E$2:$E$5)} -> 2450 | AC29: =Y29-AA29 -> -15 | AD29: =IF(N29<=0,"",AC29) | AE29: =IF(N29<=0,"",IFERROR(AC29/Y29,0))
A30: 1028 | B30: =if(countif($A$2:$A1007,A30)>1,"Duplicates","Ok") -> Ok | C30: 17/02/2025 | D30: 45705 | E30: C014 | F30: =if(E30:E1028="","Unknown",E30:E1028) -> C014 | G30: ELENA DUMITRU | H30: Elena Dumitru | I30: BUCURESTI | J30: {=_xlfn.XLOOKUP(I30,Lookup!$D$2:$D$11,Lookup!$E$2:$E$11,I30)} -> Bucuresti | K30: Laptop Lenovo | L30: Electronics | M30: =VLOOKUP(L30,Lookup!G:H,2,FALSE) -> Electronics | N30: 4 | O30: =IF(N30<0,"Negative Quantity",IF(N30=0,"Zero Quantity","OK")) -> OK | P30: 3500 | Q30: =ABS(P30) -> 3500 | R30: =IF(P30<0,"Negative Quantity",IF(P30>=0,"OK")) -> OK | S30: 15 | T30: =if(S30:S1028="","0",S30:S1028) -> 15 | U30: card | V30: =IF(U30="","Unknown",IFERROR(VLOOKUP(U30,Lookup!$A$2:$B$6,2,FALSE),U30)) -> Card | W30: George | X30: =if(W30:W1028="","Unknown",W30:W1028) -> George | Y30: =(N30*Q30)-T30 -> 13985 | Z30: =IF(N30<0,"Possible Return",IF(N30=0,"Invalid - Zero Quantity",IF(O30<0,"Invalid - Negative Price","Sale"))) -> Sale | AA30: =N30*AB30 -> 9800 | AB30: {=_xlfn.XLOOKUP(K30,Products!$B$2:$B$5,Products!$E$2:$E$5)} -> 2450 | AC30: =Y30-AA30 -> 4185 | AD30: =IF(N30<=0,"",AC30) -> 4185 | AE30: =IF(N30<=0,"",IFERROR(AC30/Y30,0)) -> 0.2992492
A31: 1029 | B31: =if(countif($A$2:$A1008,A31)>1,"Duplicates","Ok") -> Ok | C31: 31/01/2025 | D31: 45688 | E31: C017 | F31: =if(E31:E1029="","Unknown",E31:E1029) -> C017 | G31: mihai ionescu | H31: Mihai Ionescu | I31: Cluj | J31: {=_xlfn.XLOOKUP(I31,Lookup!$D$2:$D$11,Lookup!$E$2:$E$11,I31)} -> Cluj-Napoca | K31: Mouse Logitech | L31: electronics | M31: =VLOOKUP(L31,Lookup!G:H,2,FALSE) -> Electronics | N31: 25 | O31: =IF(N31<0,"Negative Quantity",IF(N31=0,"Zero Quantity","OK")) -> OK | P31: 120 | Q31: =ABS(P31) -> 120 | R31: =IF(P31<0,"Negative Quantity",IF(P31>=0,"OK")) -> OK | S31: 5 | T31: =if(S31:S1029="","0",S31:S1029) -> 5 | U31: Cash | V31: =IF(U31="","Unknown",IFERROR(VLOOKUP(U31,Lookup!$A$2:$B$6,2,FALSE),U31)) -> Cash | W31: Andrei | X31: =if(W31:W1029="","Unknown",W31:W1029) -> Andrei | Y31: =(N31*Q31)-T31 -> 2995 | Z31: =IF(N31<0,"Possible Return",IF(N31=0,"Invalid - Zero Quantity",IF(O31<0,"Invalid - Negative Price","Sale"))) -> Sale | AA31: =N31*AB31 -> 2100 | AB31: {=_xlfn.XLOOKUP(K31,Products!$B$2:$B$5,Products!$E$2:$E$5)} -> 84 | AC31: =Y31-AA31 -> 895 | AD31: =IF(N31<=0,"",AC31) -> 895 | AE31: =IF(N31<=0,"",IFERROR(AC31/Y31,0)) -> 0.29883139
A32: 1030 | B32: =if(countif($A$2:$A1009,A32)>1,"Duplicates","Ok") -> Ok | C32: 15-Jan-25 | D32: 45672 | E32: C020 | F32: =if(E32:E1030="","Unknown",E32:E1030) -> C020 | G32: ELENA DUMITRU | H32: Elena Dumitru | I32: Cluj-Napoca | J32: {=_xlfn.XLOOKUP(I32,Lookup!$D$2:$D$11,Lookup!$E$2:$E$11,I32)} -> Cluj-Napoca | K32: Mouse Logitech | L32: electronics | M32: =VLOOKUP(L32,Lookup!G:H,2,FALSE) -> Electronics | N32: -1 | O32: =IF(N32<0,"Negative Quantity",IF(N32=0,"Zero Quantity","OK")) -> Negative Quantity | P32: 120 | Q32: =ABS(P32) -> 120 | R32: =IF(P32<0,"Negative Quantity",IF(P32>=0,"OK")) -> OK | T32: =if(S32:S1030="","0",S32:S1030) -> 0 | V32: =IF(U32="","Unknown",IFERROR(VLOOKUP(U32,Lookup!$A$2:$B$6,2,FALSE),U32)) -> Unknown | W32: Andrei | X32: =if(W32:W1030="","Unknown",W32:W1030) -> Andrei | Y32: =(N32*Q32)-T32 -> -120 | Z32: =IF(N32<0,"Possible Return",IF(N32=0,"Invalid - Zero Quantity",IF(O32<0,"Invalid - Negative Price","Sale"))) -> Possible Return | AA32: =N32*AB32 -> -84 | AB32: {=_xlfn.XLOOKUP(K32,Products!$B$2:$B$5,Products!$E$2:$E$5)} -> 84 | AC32: =Y32-AA32 -> -36 | AD32: =IF(N32<=0,"",AC32) | AE32: =IF(N32<=0,"",IFERROR(AC32/Y32,0))
A33: 1031 | B33: =if(countif($A$2:$A1010,A33)>1,"Duplicates","Ok") -> Ok | C33: 28/01/2025 | D33: 45685 | E33: C002 | F33: =if(E33:E1031="","Unknown",E33:E1031) -> C002 | G33: mihai ionescu | H33: Mihai Ionescu | I33: Buc. | J33: {=_xlfn.XLOOKUP(I33,Lookup!$D$2:$D$11,Lookup!$E$2:$E$11,I33)} -> Bucuresti | K33: Monitor Dell | L33: Electro | M33: =VLOOKUP(L33,Lookup!G:H,2,FALSE) -> Electronics | N33: -1 | O33: =IF(N33<0,"Negative Quantity",IF(N33=0,"Zero Quantity","OK")) -> Negative Quantity | P33: 950 | Q33: =ABS(P33) -> 950 | R33: =IF(P33<0,"Negative Quantity",IF(P33>=0,"OK")) -> OK | S33: 10 | T33: =if(S33:S1031="","0",S33:S1031) -> 10 | U33: Card | V33: =IF(U33="","Unknown",IFERROR(VLOOKUP(U33,Lookup!$A$2:$B$6,2,FALSE),U33)) -> Card | W33: Andrei | X33: =if(W33:W1031="","Unknown",W33:W1031) -> Andrei | Y33: =(N33*Q33)-T33 -> -960 | Z33: =IF(N33<0,"Possible Return",IF(N33=0,"Invalid - Zero Quantity",IF(O33<0,"Invalid - Negative Price","Sale"))) -> Possible Return | AA33: =N33*AB33 -> -665 | AB33: {=_xlfn.XLOOKUP(K33,Products!$B$2:$B$5,Products!$E$2:$E$5)} -> 665 | AC33: =Y33-AA33 -> -295 | AD33: =IF(N33<=0,"",AC33) | AE33: =IF(N33<=0,"",IFERROR(AC33/Y33,0))
A34: 1032 | B34: =if(countif($A$2:$A1011,A34)>1,"Duplicates","Ok") -> Ok | C34: 20-Feb-25 | D34: 45708 | E34: C008 | F34: =if(E34:E1032="","Unknown",E34:E1032) -> C008 | G34: mihai ionescu | H34: Mihai Ionescu | I34: Buc. | J34: {=_xlfn.XLOOKUP(I34,Lookup!$D$2:$D$11,Lookup!$E$2:$E$11,I34)} -> Bucuresti | K34: Monitor Dell | L34: Electro | M34: =VLOOKUP(L34,Lookup!G:H,2,FALSE) -> Electronics | N34: -1 | O34: =IF(N34<0,"Negative Quantity",IF(N34=0,"Zero Quantity","OK")) -> Negative Quantity | P34: 950 | Q34: =ABS(P34) -> 950 | R34: =IF(P34<0,"Negative Quantity",IF(P34>=0,"OK")) -> OK | S34: 15 | T34: =if(S34:S1032="","0",S34:S1032) -> 15 | U34: card | V34: =IF(U34="","Unknown",IFERROR(VLOOKUP(U34,Lookup!$A$2:$B$6,2,FALSE),U34)) -> Card | W34: George | X34: =if(W34:W1032="","Unknown",W34:W1032) -> George | Y34: =(N34*Q34)-T34 -> -965 | Z34: =IF(N34<0,"Possible Return",IF(N34=0,"Invalid - Zero Quantity",IF(O34<0,"Invalid - Negative Price","Sale"))) -> Possible Return | AA34: =N34*AB34 -> -665 | AB34: {=_xlfn.XLOOKUP(K34,Products!$B$2:$B$5,Products!$E$2:$E$5)} -> 665 | AC34: =Y34-AA34 -> -300 | AD34: =IF(N34<=0,"",AC34) | AE34: =IF(N34<=0,"",IFERROR(AC34/Y34,0))
A35: 1033 | B35: =if(countif($A$2:$A1012,A35)>1,"Duplicates","Ok") -> Ok | C35: 2025-01-15 | D35: 45672 | E35: C022 | F35: =if(E35:E1033="","Unknown",E35:E1033) -> C022 | G35: alex marin | H35: Alex Marin | I35: BUCURESTI | J35: {=_xlfn.XLOOKUP(I35,Lookup!$D$2:$D$11,Lookup!$E$2:$E$11,I35)} -> Bucuresti | K35: Monitor Dell | L35: Electro | M35: =VLOOKUP(L35,Lookup!G:H,2,FALSE) -> Electronics | N35: 25 | O35: =IF(N35<0,"Negative Quantity",IF(N35=0,"Zero Quantity","OK")) -> OK | P35: -950 | Q35: =ABS(P35) -> 950 | R35: =IF(P35<0,"Negative Quantity",IF(P35>=0,"OK")) -> Negative Quantity | T35: =if(S35:S1033="","0",S35:S1033) -> 0 | U35: Transfer | V35: =IF(U35="","Unknown",IFERROR(VLOOKUP(U35,Lookup!$A$2:$B$6,2,FALSE),U35)) -> Bank Transfer | W35: Maria | X35: =if(W35:W1033="","Unknown",W35:W1033) -> Maria | Y35: =(N35*Q35)-T35 -> 23750 | Z35: =IF(N35<0,"Possible Return",IF(N35=0,"Invalid - Zero Quantity",IF(O35<0,"Invalid - Negative Price","Sale"))) -> Sale | AA35: =N35*AB35 -> 16625 | AB35: {=_xlfn.XLOOKUP(K35,Products!$B$2:$B$5,Products!$E$2:$E$5)} -> 665 | AC35: =Y35-AA35 -> 7125 | AD35: =IF(N35<=0,"",AC35) -> 7125 | AE35: =IF(N35<=0,"",IFERROR(AC35/Y35,0)) -> 0.3
A36: 1034 | B36: =if(countif($A$2:$A1013,A36)>1,"Duplicates","Ok") -> Ok | C36: 18/01/2025 | D36: 45675 | E36: C021 | F36: =if(E36:E1034="","Unknown",E36:E1034) -> C021 | G36: MARIA ilie | H36: Maria Ilie | I36: Buc. | J36: {=_xlfn.XLOOKUP(I36,Lookup!$D$2:$D$11,Lookup!$E$2:$E$11,I36)} -> Bucuresti | K36: Office Chair | L36: Furniture | M36: =VLOOKUP(L36,Lookup!G:H,2,FALSE) -> Furniture | N36: 4 | O36: =IF(N36<0,"Negative Quantity",IF(N36=0,"Zero Quantity","OK")) -> OK | P36: 800 | Q36: =ABS(P36) -> 800 | R36: =IF(P36<0,"Negative Quantity",IF(P36>=0,"OK")) -> OK | S36: 15 | T36: =if(S36:S1034="","0",S36:S1034) -> 15 | U36: Card | V36: =IF(U36="","Unknown",IFERROR(VLOOKUP(U36,Lookup!$A$2:$B$6,2,FALSE),U36)) -> Card | W36: George | X36: =if(W36:W1034="","Unknown",W36:W1034) -> George | Y36: =(N36*Q36)-T36 -> 3185 | Z36: =IF(N36<0,"Possible Return",IF(N36=0,"Invalid - Zero Quantity",IF(O36<0,"Invalid - Negative Price","Sale"))) -> Sale | AA36: =N36*AB36 -> 2240 | AB36: {=_xlfn.XLOOKUP(K36,Products!$B$2:$B$5,Products!$E$2:$E$5)} -> 560 | AC36: =Y36-AA36 -> 945 | AD36: =IF(N36<=0,"",AC36) -> 945 | AE36: =IF(N36<=0,"",IFERROR(AC36/Y36,0)) -> 0.2967033
A37: 1035 | B37: =if(countif($A$2:$A1014,A37)>1,"Duplicates","Ok") -> Ok | C37: 08-Feb-25 | D37: 45696 | E37: C022 | F37: =if(E37:E1035="","Unknown",E37:E1035) -> C022 | G37: alex marin | H37: Alex Marin | I37: București | J37: {=_xlfn.XLOOKUP(I37,Lookup!$D$2:$D$11,Lookup!$E$2:$E$11,I37)} -> Bucuresti | K37: Office Chair | L37: Furniture | M37: =VLOOKUP(L37,Lookup!G:H,2,FALSE) -> Furniture | N37: -1 | O37: =IF(N37<0,"Negative Quantity",IF(N37=0,"Zero Quantity","OK")) -> Negative Quantity | P37: 800 | Q37: =ABS(P37) -> 800 | R37: =IF(P37<0,"Negative Quantity",IF(P37>=0,"OK")) -> OK | S37: 5 | T37: =if(S37:S1035="","0",S37:S1035) -> 5 | U37: Card | V37: =IF(U37="","Unknown",IFERROR(VLOOKUP(U37,Lookup!$A$2:$B$6,2,FALSE),U37)) -> Card | W37: George | X37: =if(W37:W1035="","Unknown",W37:W1035) -> George | Y37: =(N37*Q37)-T37 -> -805 | Z37: =IF(N37<0,"Possible Return",IF(N37=0,"Invalid - Zero Quantity",IF(O37<0,"Invalid - Negative Price","Sale"))) -> Possible Return | AA37: =N37*AB37 -> -560 | AB37: {=_xlfn.XLOOKUP(K37,Products!$B$2:$B$5,Products!$E$2:$E$5)} -> 560 | AC37: =Y37-AA37 -> -245 | AD37: =IF(N37<=0,"",AC37) | AE37: =IF(N37<=0,"",IFERROR(AC37/Y37,0))
A38: 1036 | B38: =if(countif($A$2:$A1015,A38)>1,"Duplicates","Ok") -> Ok | C38: 2025-02-12 | D38: 45700 | E38: C008 | F38: =if(E38:E1036="","Unknown",E38:E1036) -> C008 | G38: Ioana Stan | H38: Ioana Stan | I38: BUCURESTI | J38: {=_xlfn.XLOOKUP(I38,Lookup!$D$2:$D$11,Lookup!$E$2:$E$11,I38)} -> Bucuresti | K38: Office Chair | L38: Furniture | M38: =VLOOKUP(L38,Lookup!G:H,2,FALSE) -> Furniture | N38: 0 | O38: =IF(N38<0,"Negative Quantity",IF(N38=0,"Zero Quantity","OK")) -> Zero Quantity | P38: 800 | Q38: =ABS(P38) -> 800 | R38: =IF(P38<0,"Negative Quantity",IF(P38>=0,"OK")) -> OK | S38: 10 | T38: =if(S38:S1036="","0",S38:S1036) -> 10 | U38: Card | V38: =IF(U38="","Unknown",IFERROR(VLOOKUP(U38,Lookup!$A$2:$B$6,2,FALSE),U38)) -> Card | W38: Maria | X38: =if(W38:W1036="","Unknown",W38:W1036) -> Maria | Y38: =(N38*Q38)-T38 -> -10 | Z38: =IF(N38<0,"Possible Return",IF(N38=0,"Invalid - Zero Quantity",IF(O38<0,"Invalid - Negative Price","Sale"))) -> Invalid - Zero Quantity | AA38: =N38*AB38 -> 0 | AB38: {=_xlfn.XLOOKUP(K38,Products!$B$2:$B$5,Products!$E$2:$E$5)} -> 560 | AC38: =Y38-AA38 -> -10 | AD38: =IF(N38<=0,"",AC38) | AE38: =IF(N38<=0,"",IFERROR(AC38/Y38,0))
A39: 1037 | B39: =if(countif($A$2:$A1016,A39)>1,"Duplicates","Ok") -> Ok | C39: 29/01/2025 | D39: 45686 | E39: C002 | F39: =if(E39:E1037="","Unknown",E39:E1037) -> C002 | G39: Ioana Stan | H39: Ioana Stan | I39: București | J39: {=_xlfn.XLOOKUP(I39,Lookup!$D$2:$D$11,Lookup!$E$2:$E$11,I39)} -> Bucuresti | K39: Mouse Logitech | L39: electronics | M39: =VLOOKUP(L39,Lookup!G:H,2,FALSE) -> Electronics | N39: 3 | O39: =IF(N39<0,"Negative Quantity",IF(N39=0,"Zero Quantity","OK")) -> OK | P39: 120 | Q39: =ABS(P39) -> 120 | R39: =IF(P39<0,"Negative Quantity",IF(P39>=0,"OK")) -> OK | S39: 10 | T39: =if(S39:S1037="","0",S39:S1037) -> 10 | U39: Transfer | V39: =IF(U39="","Unknown",IFERROR(VLOOKUP(U39,Lookup!$A$2:$B$6,2,FALSE),U39)) -> Bank Transfer | W39: George | X39: =if(W39:W1037="","Unknown",W39:W1037) -> George | Y39: =(N39*Q39)-T39 -> 350 | Z39: =IF(N39<0,"Possible Return",IF(N39=0,"Invalid - Zero Quantity",IF(O39<0,"Invalid - Negative Price","Sale"))) -> Sale | AA39: =N39*AB39 -> 252 | AB39: {=_xlfn.XLOOKUP(K39,Products!$B$2:$B$5,Products!$E$2:$E$5)} -> 84 | AC39: =Y39-AA39 -> 98 | AD39: =IF(N39<=0,"",AC39) -> 98 | AE39: =IF(N39<=0,"",IFERROR(AC39/Y39,0)) -> 0.28
A40: 1038 | B40: =if(countif($A$2:$A1017,A40)>1,"Duplicates","Ok") -> Ok | C40: 2025-01-05 | D40: 45662 | E40: C001 | F40: =if(E40:E1038="","Unknown",E40:E1038) -> C001 | G40: alex marin | H40: Alex Marin | I40: București | J40: {=_xlfn.XLOOKUP(I40,Lookup!$D$2:$D$11,Lookup!$E$2:$E$11,I40)} -> Bucuresti | K40: Monitor Dell | L40: Electro | M40: =VLOOKUP(L40,Lookup!G:H,2,FALSE) -> Electronics | N40: 5 | O40: =IF(N40<0,"Negative Quantity",IF(N40=0,"Zero Quantity","OK")) -> OK | P40: 950 | Q40: =ABS(P40) -> 950 | R40: =IF(P40<0,"Negative Quantity",IF(P40>=0,"OK")) -> OK | S40: 15 | T40: =if(S40:S1038="","0",S40:S1038) -> 15 | U40: Card | V40: =IF(U40="","Unknown",IFERROR(VLOOKUP(U40,Lookup!$A$2:$B$6,2,FALSE),U40)) -> Card | W40: Andrei | X40: =if(W40:W1038="","Unknown",W40:W1038) -> Andrei | Y40: =(N40*Q40)-T40 -> 4735 | Z40: =IF(N40<0,"Possible Return",IF(N40=0,"Invalid - Zero Quantity",IF(O40<0,"Invalid - Negative Price","Sale"))) -> Sale | AA40: =N40*AB40 -> 3325 | AB40: {=_xlfn.XLOOKUP(K40,Products!$B$2:$B$5,Products!$E$2:$E$5)} -> 665 | AC40: =Y40-AA40 -> 1410 | AD40: =IF(N40<=0,"",AC40) -> 1410 | AE40: =IF(N40<=0,"",IFERROR(AC40/Y40,0)) -> 0.29778247
...

Sheet Lookup
A1: PaymentMethod | B1: PaymentMethod_Clean | D1: Original | E1: Standard | G1: Original | H1: Standard | J1: Original | K1: Standard
A2: card | B2: Card | D2: CJ | E2: Cluj-Napoca | G2: Electronics | H2: Electronics | J2: Laptop Lenovo | K2: 3500
A3: Card | B3: Card | D3: Iasi | E3: Iasi | G3: electronics | H3: Electronics | J3: Mouse Logitech | K3: 120
A4: Transfer | B4: Bank Transfer | D4: București | E4: Bucuresti | G4: Electro | H4: Electronics | J4: Monitor Dell | K4: 950
A5: Bank Transfer | B5: Bank Transfer | D5: Buc. | E5: Bucuresti | G5: Furniture | H5: Furniture | J5: Office Chair | K5: 800
A6: Cash | B6: Cash | D6: Cluj | E6: Cluj-Napoca | G6: furniture | H6: Furniture
A7: Unknown | B7: Unknown | D7: BUCURESTI | E7: Bucuresti
D8: Bucuresti | E8: Bucuresti
D9: Cluj-Napoca | E9: Cluj-Napoca
D10: Cluj | E10: Cluj-Napoca
D11: Iași | E11: Iasi

Sheet Orders_Raw
A1: OrderID | B1: OrderDate | C1: CustomerID | D1: CustomerName | E1: City | F1: Product | G1: Category | H1: Quantity | I1: UnitPrice | J1: Discount | K1: PaymentMethod | L1: SalesPerson
A2: 1000 | B2: 10/02/2025 | C2: C004 | D2: Ana Popescu | E2: CJ | F2: Monitor Dell | G2: Electro | H2: 5 | I2: 950 | J2: 120 | K2: Bank Transfer | L2: Andrei
A3: 1001 | B3: 2025-01-18 | C3: C010 | D3: ELENA DUMITRU | E3: Iasi | F3: Mouse Logitech | G3: electronics | H3: -1 | I3: 120 | J3: 120 | K3: Transfer | L3: Maria
A4: 1002 | B4: 2025-01-08 | C4: C012 | D4: ELENA DUMITRU | E4: București | F4: Mouse Logitech | G4: electronics | H4: 25 | I4: 120 | J4: 120 | K4: Bank Transfer
A5: 1003 | B5: 25-Jan-25 | C5: C002 | D5: mihai ionescu | E5: Buc. | F5: Laptop Lenovo | G5: Electronics | H5: -1 | I5: 3500 | J5: 5 | K5: Cash | L5: George
A6: 1004 | B6: 2025-02-18 | C6: C011 | D6: MARIA ilie | E6: Bucuresti | F6: Laptop Lenovo | G6: Electronics | H6: 25 | I6: 3500 | J6: 0 | L6: George
A7: 1005 | B7: 15-Jan-25 | C7: C010 | D7: MARIA ilie | E7: CJ | F7: Laptop Lenovo | G7: Electronics | H7: 25 | I7: 3500 | J7: 120 | L7: Maria
A8: 1006 | B8: 02-Jan-25 | C8: C025 | D8: ELENA DUMITRU | E8: București | F8: Monitor Dell | G8: Electro | H8: 25 | I8: 950 | J8: 0 | K8: card
A9: 1007 | B9: 2025-02-26 | C9: C014 | D9: mihai ionescu | E9: Buc. | F9: Mouse Logitech | G9: electronics | H9: 1 | I9: -120 | J9: 15 | K9: Cash | L9: Andrei
A10: 1008 | B10: 15-Feb-25 | C10: C023 | D10: MARIA ilie | E10: Cluj | F10: Mouse Logitech | G10: electronics | H10: -1 | I10: 120 | J10: 5 | K10: Transfer | L10: Andrei
A11: 1009 | B11: 18-Feb-25 | C11: C005 | D11: mihai ionescu | E11: CJ | F11: Office Chair | G11: Furniture | H11: 25 | I11: 800 | J11: 10 | L11: Maria
A12: 1010 | B12: 16-Feb-25 | C12: C009 | D12: mihai ionescu | E12: CJ | F12: Laptop Lenovo | G12: Electronics | H12: 2 | I12: 3500 | K12: Cash | L12: George
A13: 1011 | B13: 13-Jan-25 | C13: C022 | D13: mihai ionescu | E13: BUCURESTI | F13: Mouse Logitech | G13: electronics | H13: 25 | I13: 120 | J13: 15 | K13: Card | L13: Andrei
A14: 1012 | B14: 2025-01-08 | C14: C021 | D14: ELENA DUMITRU | E14: Bucuresti | F14: Laptop Lenovo | G14: Electronics | H14: 25 | I14: 3500 | J14: 10
A15: 1013 | B15: 15/01/2025 | C15: C016 | D15: Ioana Stan | E15: CJ | F15: Mouse Logitech | G15: electronics | H15: -1 | I15: 120 | J15: 10 | K15: Cash
A16: 1014 | B16: 13/01/2025 | C16: C024 | D16: MARIA ilie | E16: Cluj-Napoca | F16: Monitor Dell | G16: Electro | H16: 3 | I16: 950 | J16: 10 | K16: card | L16: Maria
A17: 1015 | B17: 01-Mar-25 | D17: Ana Popescu | E17: București | F17: Monitor Dell | G17: Electro | H17: 0 | I17: 950 | L17: Maria
A18: 1016 | B18: 07-Jan-25 | C18: C011 | D18: Ioana Stan | E18: CJ | F18: Monitor Dell | G18: Electro | H18: 25 | I18: 950 | J18: 120 | K18: card | L18: George
A19: 1017 | B19: 2025-01-13 | C19: C015 | D19: mihai ionescu | E19: Cluj-Napoca | F19: Office Chair | G19: Furniture | H19: 25 | I19: 800 | J19: 15
A20: 1018 | B20: 11-Jan-25 | C20: C013 | D20: mihai ionescu | E20: Cluj | F20: Mouse Logitech | G20: electronics | H20: 25 | I20: 120 | K20: Bank Transfer | L20: Andrei
A21: 1019 | B21: 14/01/2025 | C21: C008 | D21: MARIA ilie | E21: Iași | F21: Mouse Logitech | G21: electronics | H21: 2 | I21: 120 | J21: 120 | K21: Transfer | L21: Andrei
A22: 1005 | B22: 2025-01-26 | D22: Ioana Stan | E22: CJ | F22: Office Chair | G22: Furniture | H22: -1 | I22: 800 | K22: card | L22: Maria
A23: 1021 | B23: 12-Jan-25 | C23: C008 | D23: Ioana Stan | E23: Buc. | F23: Monitor Dell | G23: Electro | H23: 0 | I23: 950 | J23: 5 | K23: Bank Transfer | L23: George
A24: 1022 | B24: 09/01/2025 | C24: C003 | D24: mihai ionescu | E24: Cluj | F24: Mouse Logitech | G24: electronics | H24: 25 | I24: 120 | J24: 10 | L24: Andrei
A25: 1023 | B25: 21/02/2025 | C25: C013 | D25: MARIA ilie | E25: Bucuresti | F25: Mouse Logitech | G25: electronics | H25: 0 | I25: 120 | J25: 15 | K25: Bank Transfer | L25: Maria
A26: 1024 | B26: 02-Mar-25 | C26: C007 | D26: Ana Popescu | E26: Iasi | F26: Mouse Logitech | G26: electronics | H26: 0 | I26: -120 | J26: 15 | K26: Cash | L26: George
A27: 1025 | B27: 2025-01-14 | C27: C016 | D27: ELENA DUMITRU | E27: BUCURESTI | F27: Laptop Lenovo | G27: Electronics | H27: 2 | I27: 3500 | J27: 120 | K27: Transfer | L27: Maria
A28: 1026 | B28: 01/02/2025 | C28: C020 | D28: alex marin | E28: Bucuresti | F28: Laptop Lenovo | G28: Electronics | H28: -1 | I28: 3500 | J28: 120 | K28: Transfer | L28: Maria
A29: 1027 | B29: 2025-02-12 | C29: C024 | D29: mihai ionescu | E29: Cluj-Napoca | F29: Laptop Lenovo | G29: Electronics | H29: 0 | I29: 3500 | J29: 15 | K29: Transfer
A30: 1028 | B30: 17/02/2025 | C30: C014 | D30: ELENA DUMITRU | E30: BUCURESTI | F30: Laptop Lenovo | G30: Electronics | H30: 4 | I30: 3500 | J30: 15 | K30: card | L30: George
A31: 1029 | B31: 31/01/2025 | C31: C017 | D31: mihai ionescu | E31: Cluj | F31: Mouse Logitech | G31: electronics | H31: 25 | I31: 120 | J31: 5 | K31: Cash | L31: Andrei
A32: 1030 | B32: 15-Jan-25 | C32: C020 | D32: ELENA DUMITRU | E32: Cluj-Napoca | F32: Mouse Logitech | G32: electronics | H32: -1 | I32: 120 | L32: Andrei
A33: 1031 | B33: 28/01/2025 | C33: C002 | D33: mihai ionescu | E33: Buc. | F33: Monitor Dell | G33: Electro | H33: -1 | I33: 950 | J33: 10 | K33: Card | L33: Andrei
A34: 1032 | B34: 20-Feb-25 | C34: C008 | D34: mihai ionescu | E34: Buc. | F34: Monitor Dell | G34: Electro | H34: -1 | I34: 950 | J34: 15 | K34: card | L34: George
A35: 1033 | B35: 2025-01-15 | C35: C022 | D35: alex marin | E35: BUCURESTI | F35: Monitor Dell | G35: Electro | H35: 25 | I35: -950 | K35: Transfer | L35: Maria
A36: 1034 | B36: 18/01/2025 | C36: C021 | D36: MARIA ilie | E36: Buc. | F36: Office Chair | G36: Furniture | H36: 4 | I36: 800 | J36: 15 | K36: Card | L36: George
A37: 1035 | B37: 08-Feb-25 | C37: C022 | D37: alex marin | E37: București | F37: Office Chair | G37: Furniture | H37: -1 | I37: 800 | J37: 5 | K37: Card | L37: George
A38: 1036 | B38: 2025-02-12 | C38: C008 | D38: Ioana Stan | E38: BUCURESTI | F38: Office Chair | G38: Furniture | H38: 0 | I38: 800 | J38: 10 | K38: Card | L38: Maria
A39: 1037 | B39: 29/01/2025 | C39: C002 | D39: Ioana Stan | E39: București | F39: Mouse Logitech | G39: electronics | H39: 3 | I39: 120 | J39: 10 | K39: Transfer | L39: George
A40: 1038 | B40: 2025-01-05 | C40: C001 | D40: alex marin | E40: București | F40: Monitor Dell | G40: Electro | H40: 5 | I40: 950 | J40: 15 | K40: Card | L40: Andrei
...

Sheet Customers
A1: CustomerID | B1: CustomerName | C1: City | D1: Email
A2: C001 | B2: Ana Popescu | C2: Cluj | D2: user1@mail.com
A3: C002 | B3: Ana Popescu | C3: București | D3: user2@mail.com
A4: C003 | B4: MARIA ilie | C4: CJ | D4: user3@mail.com
A5: C004 | B5: Ana Popescu | C5: Buc. | D5: user4@mail.com
A6: C005 | B6: MARIA ilie | C6: Iasi | D6: user5@mail.com
A7: C006 | B7: Ana Popescu | C7: CJ | D7: user6@mail.com
A8: C007 | B8: MARIA ilie | C8: Cluj-Napoca | D8: user7mail.com
A9: C008 | B9: mihai ionescu | C9: CJ | D9: user8@mail.com
A10: C009 | B10: alex marin | C10: Iasi | D10: user9@mail.com
A11: C010 | B11: MARIA ilie | C11: Cluj | D11: user10@mail.com
A12: C011 | B12: MARIA ilie | C12: Iași | D12: user11@mail.com
... A26: C025 | B26: ELENA DUMITRU | C26: Iași | D26: user25@mail.com

Sheet Products
A1: ProductID | B1: ProductName | C1: Category | D1: UnitPrice | E1: CostPrice
A2: P001 | B2: Laptop Lenovo | C2: Electronics | D2: 3500 | E2: 2450
A3: P002 | B3: Mouse Logitech | C3: electronics | D3: 120 | E3: 84
A4: P003 | B4: Monitor Dell | C4: Electro | D4: 950 | E4: 665
A5: P004 | B5: Office Chair | C5: Furniture | D5: 800 | E5: 560

Sheet Salespersons
A1: SalesPersonID | B1: SalesPerson
A2: S01 | B2: Andrei
A3: S02 | B3: Maria
A4: S03 | B4: George
A5: S04 | B5: Elena
